Workbook

Sheet PT2018
A1: Población Total Censada 2018
A3: Municpios y edades simples | E3: Total | F3: Sexo | H3: Cabecera | K3: Centro Poblado | N3: Rural disperso
F4: Hombre | G4: Mujer | H4: Total | I4: Hombre | J4: Mujer | K4: Total | L4: Hombre | M4: Mujer | N4: Total | O4: Hombre | P4: Mujer
A5: 44_La Guajira | B5: 44001_Riohacha | C5: 0 a 4 | D5: 0 | E5: 3970 | F5: 1999 | G5: 1971 | H5: 2416 | I5: 1213 | J5: 1203 | K5: 346 | L5: 189 | M5: 157 | N5: 1208 | O5: 597 | P5: 611
D6: 1 | E6: 4108 | F6: 2066 | G6: 2042 | H6: 2382 | I6: 1177 | J6: 1205 | K6: 375 | L6: 188 | M6: 187 | N6: 1351 | O6: 701 | P6: 650
D7: 2 | E7: 4216 | F7: 2100 | G7: 2116 | H7: 2455 | I7: 1263 | J7: 1192 | K7: 375 | L7: 193 | M7: 182 | N7: 1386 | O7: 644 | P7: 742
D8: 3 | E8: 4207 | F8: 2141 | G8: 2066 | H8: 2422 | I8: 1254 | J8: 1168 | K8: 372 | L8: 185 | M8: 187 | N8: 1413 | O8: 702 | P8: 711
D9: 4 | E9: 3955 | F9: 2037 | G9: 1918 | H9: 2271 | I9: 1178 | J9: 1093 | K9: 323 | L9: 156 | M9: 167 | N9: 1361 | O9: 703 | P9: 658
D10: Total grupo edad | E10: 20456 | F10: 10343 | G10: 10113 | H10: 11946 | I10: 6085 | J10: 5861 | K10: 1791 | L10: 911 | M10: 880 | N10: 6719 | O10: 3347 | P10: 3372
C11: 5 a 9 | D11: 5 | E11: 4051 | F11: 2094 | G11: 1957 | H11: 2315 | I11: 1223 | J11: 1092 | K11: 423 | L11: 225 | M11: 198 | N11: 1313 | O11: 646 | P11: 667
D12: 6 | E12: 4235 | F12: 2132 | G12: 2103 | H12: 2490 | I12: 1254 | J12: 1236 | K12: 386 | L12: 189 | M12: 197 | N12: 1359 | O12: 689 | P12: 670
D13: 7 | E13: 4042 | F13: 2070 | G13: 1972 | H13: 2461 | I13: 1248 | J13: 1213 | K13: 376 | L13: 190 | M13: 186 | N13: 1205 | O13: 632 | P13: 573
D14: 8 | E14: 3944 | F14: 1977 | G14: 1967 | H14: 2421 | I14: 1227 | J14: 1194 | K14: 373 | L14: 182 | M14: 191 | N14: 1150 | O14: 568 | P14: 582
D15: 9 | E15: 3959 | F15: 2023 | G15: 1936 | H15: 2421 | I15: 1255 | J15: 1166 | K15: 397 | L15: 197 | M15: 200 | N15: 1141 | O15: 571 | P15: 570
D16: Total grupo edad | E16: 20231 | F16: 10296 | G16: 9935 | H16: 12108 | I16: 6207 | J16: 5901 | K16: 1955 | L16: 983 | M16: 972 | N16: 6168 | O16: 3106 | P16: 3062
C17: 10 a 14 | D17: 10 | E17: 3849 | F17: 1980 | G17: 1869 | H17: 2378 | I17: 1232 | J17: 1146 | K17: 368 | L17: 178 | M17: 190 | N17: 1103 | O17: 570 | P17: 533
D18: 11 | E18: 3874 | F18: 1977 | G18: 1897 | H18: 2439 | I18: 1246 | J18: 1193 | K18: 366 | L18: 198 | M18: 168 | N18: 1069 | O18: 533 | P18: 536
D19: 12 | E19: 3576 | F19: 1776 | G19: 1800 | H19: 2248 | I19: 1105 | J19: 1143 | K19: 342 | L19: 171 | M19: 171 | N19: 986 | O19: 500 | P19: 486
D20: 13 | E20: 3631 | F20: 1853 | G20: 1778 | H20: 2301 | I20: 1162 | J20: 1139 | K20: 360 | L20: 207 | M20: 153 | N20: 970 | O20: 484 | P20: 486
D21: 14 | E21: 3508 | F21: 1783 | G21: 1725 | H21: 2269 | I21: 1120 | J21: 1149 | K21: 342 | L21: 215 | M21: 127 | N21: 897 | O21: 448 | P21: 449
D22: Total grupo edad | E22: 18438 | F22: 9369 | G22: 9069 | H22: 11635 | I22: 5865 | J22: 5770 | K22: 1778 | L22: 969 | M22: 809 | N22: 5025 | O22: 2535 | P22: 2490
C23: 15 a 19 | D23: 15 | E23: 3445 | F23: 1690 | G23: 1755 | H23: 2275 | I23: 1130 | J23: 1145 | K23: 323 | L23: 160 | M23: 163 | N23: 847 | O23: 400 | P23: 447
D24: 16 | E24: 3358 | F24: 1633 | G24: 1725 | H24: 2152 | I24: 1042 | J24: 1110 | K24: 339 | L24: 174 | M24: 165 | N24: 867 | O24: 417 | P24: 450
D25: 17 | E25: 3599 | F25: 1765 | G25: 1834 | H25: 2413 | I25: 1176 | J25: 1237 | K25: 352 | L25: 171 | M25: 181 | N25: 834 | O25: 418 | P25: 416
D26: 18 | E26: 3959 | F26: 2028 | G26: 1931 | H26: 2671 | I26: 1359 | J26: 1312 | K26: 336 | L26: 181 | M26: 155 | N26: 952 | O26: 488 | P26: 464
D27: 19 | E27: 3545 | F27: 1781 | G27: 1764 | H27: 2397 | I27: 1156 | J27: 1241 | K27: 250 | L27: 135 | M27: 115 | N27: 898 | O27: 490 | P27: 408
D28: Total grupo edad | E28: 17906 | F28: 8897 | G28: 9009 | H28: 11908 | I28: 5863 | J28: 6045 | K28: 1600 | L28: 821 | M28: 779 | N28: 4398 | O28: 2213 | P28: 2185
C29: 20 a 24 | D29: 20 | E29: 3488 | F29: 1767 | G29: 1721 | H29: 2380 | I29: 1185 | J29: 1195 | K29: 261 | L29: 138 | M29: 123 | N29: 847 | O29: 444 | P29: 403
D30: 21 | E30: 3233 | F30: 1624 | G30: 1609 | H30: 2200 | I30: 1082 | J30: 1118 | K30: 262 | L30: 133 | M30: 129 | N30: 771 | O30: 409 | P30: 362
D31: 22 | E31: 3448 | F31: 1723 | G31: 1725 | H31: 2381 | I31: 1187 | J31: 1194 | K31: 290 | L31: 136 | M31: 154 | N31: 777 | O31: 400 | P31: 377
D32: 23 | E32: 3440 | F32: 1658 | G32: 1782 | H32: 2449 | I32: 1165 | J32: 1284 | K32: 263 | L32: 136 | M32: 127 | N32: 728 | O32: 357 | P32: 371
D33: 24 | E33: 3214 | F33: 1527 | G33: 1687 | H33: 2284 | I33: 1065 | J33: 1219 | K33: 260 | L33: 129 | M33: 131 | N33: 670 | O33: 333 | P33: 337
D34: Total grupo edad | E34: 16823 | F34: 8299 | G34: 8524 | H34: 11694 | I34: 5684 | J34: 6010 | K34: 1336 | L34: 672 | M34: 664 | N34: 3793 | O34: 1943 | P34: 1850
C35: 25 a 29 | D35: 25 | E35: 3226 | F35: 1555 | G35: 1671 | H35: 2331 | I35: 1119 | J35: 1212 | K35: 248 | L35: 117 | M35: 131 | N35: 647 | O35: 319 | P35: 328
D36: 26 | E36: 3105 | F36: 1484 | G36: 1621 | H36: 2240 | I36: 1045 | J36: 1195 | K36: 257 | L36: 134 | M36: 123 | N36: 608 | O36: 305 | P36: 303
D37: 27 | E37: 2945 | F37: 1374 | G37: 1571 | H37: 2198 | I37: 1028 | J37: 1170 | K37: 233 | L37: 106 | M37: 127 | N37: 514 | O37: 240 | P37: 274
D38: 28 | E38: 2863 | F38: 1395 | G38: 1468 | H38: 2110 | I38: 1002 | J38: 1108 | K38: 254 | L38: 129 | M38: 125 | N38: 499 | O38: 264 | P38: 235
D39: 29 | E39: 2896 | F39: 1431 | G39: 1465 | H39: 2125 | I39: 1052 | J39: 1073 | K39: 226 | L39: 107 | M39: 119 | N39: 545 | O39: 272 | P39: 273
D40: Total grupo edad | E40: 15035 | F40: 7239 | G40: 7796 | H40: 11004 | I40: 5246 | J40: 5758 | K40: 1218 | L40: 593 | M40: 625 | N40: 2813 | O40: 1400 | P40: 1413
C41: 30 a 34 | D41: 30 | E41: 2889 | F41: 1418 | G41: 1471 | H41: 1967 | I41: 966 | J41: 1001 | K41: 218 | L41: 100 | M41: 118 | N41: 704 | O41: 352 | P41: 352
...

Sheet DF2018
A2: 44 La Guajira
A3: Departamento, municipio y área de residencia | C3: TOTAL | D3: Total | G3: Grupos de edad
G4: Menor 1 hora | J4: De 1 a 23 horas | M4: De 1 a 6 días | P4: De 7 a 27 dias | S4: De 28 a 29 días | V4: De 1 a 5 meses | Y4: De 6 a 11 meses | AB4: De 1 año | AE4: De 2 a 4 años | AH4: De 5 a 9 años | AK4: De 10 a 14 años | AN4: De 15 a 19 años | AQ4: De 20 a 24 años | AT4: De 25 a 29 años | AW4: De 30 a 34 años | AZ4: De 35 a 39 años | BC4: De 40 a 44 años | BF4: De 45 a 49 años | BI4: De 50 a 54 años | BL4: De 55 a 59 años | BO4: De 60 a 64 años | BR4: De 65 a 69 años | BU4: De 70 a 74 años | BX4: De 75 a 79 años | CA4: De 80 a 84 años | CD4: De 85 a 89 años | CG4: De 90 a 94 años | CJ4: De 95 a 99 años | CM4: De 100 años y más | CP4: Edad desconocida
D5: Hombres | E5: Mujeres | F5: Indeterminado | G5: Hombres | H5: Mujeres | I5: Indeterminado | J5: Hombres | K5: Mujeres | L5: Indeterminado | M5: Hombres | N5: Mujeres | O5: Indeterminado | P5: Hombres | Q5: Mujeres | R5: Indeterminado | S5: Hombres | T5: Mujeres | U5: Indeterminado | V5: Hombres | W5: Mujeres | X5: Indeterminado | Y5: Hombres | Z5: Mujeres | AA5: Indeterminado | AB5: Hombres | AC5: Mujeres | AD5: Indeterminado | AE5: Hombres | AF5: Mujeres | AG5: Indeterminado | AH5: Hombres | AI5: Mujeres | AJ5: Indeterminado | AK5: Hombres | AL5: Mujeres | AM5: Indeterminado | AN5: Hombres | AO5: Mujeres | AP5: Indeterminado | AQ5: Hombres | AR5: Mujeres | AS5: Indeterminado | AT5: Hombres | AU5: Mujeres | AV5: Indeterminado | AW5: Hombres | AX5: Mujeres | AY5: Indeterminado | AZ5: Hombres | BA5: Mujeres | BB5: Indeterminado | BC5: Hombres | BD5: Mujeres | BE5: Indeterminado | BF5: Hombres | BG5: Mujeres | BH5: Indeterminado | BI5: Hombres | BJ5: Mujeres | BK5: Indeterminado | BL5: Hombres | BM5: Mujeres | BN5: Indeterminado | BO5: Hombres | BP5: Mujeres | BQ5: Indeterminado | BR5: Hombres | BS5: Mujeres | BT5: Indeterminado | BU5: Hombres | BV5: Mujeres | BW5: Indeterminado | BX5: Hombres | BY5: Mujeres | BZ5: Indeterminado | CA5: Hombres | CB5: Mujeres | CC5: Indeterminado | CD5: Hombres | CE5: Mujeres | CF5: Indeterminado | CG5: Hombres | CH5: Mujeres | CI5: Indeterminado | CJ5: Hombres | CK5: Mujeres | CL5: Indeterminado | CM5: Hombres | CN5: Mujeres | CO5: Indeterminado | CP5: Hombres | CQ5: Mujeres | CR5: Indeterminado
A6: TOTAL | B6: TOTAL | C6: 2759 | D6: 1546 | E6: 1213 | F6: 0 | G6: 2 | H6: 5 | I6: 0 | J6: 34 | K6: 18 | L6: 0 | M6: 49 | N6: 33 | O6: 0 | P6: 28 | Q6: 35 | R6: 0 | S6: 0 | T6: 0 | U6: 0 | V6: 52 | W6: 63 | X6: 0 | Y6: 51 | Z6: 29 | AA6: 0 | AB6: 43 | AC6: 28 | AD6: 0 | AE6: 33 | AF6: 28 | AG6: 0 | AH6: 20 | AI6: 10 | AJ6: 0 | AK6: 12 | AL6: 18 | AM6: 0 | AN6: 47 | AO6: 25 | AP6: 0 | AQ6: 67 | AR6: 18 | AS6: 0 | AT6: 70 | AU6: 25 | AV6: 0 | AW6: 55 | AX6: 29 | AY6: 0 | AZ6: 60 | BA6: 37 | BB6: 0 | BC6: 49 | BD6: 43 | BE6: 0 | BF6: 56 | BG6: 34 | BH6: 0 | BI6: 64 | BJ6: 54 | BK6: 0 | BL6: 85 | BM6: 68 | BN6: 0 | BO6: 93 | BP6: 70 | BQ6: 0 | BR6: 112 | BS6: 84 | BT6: 0 | BU6: 103 | BV6: 73 | BW6: 0 | BX6: 104 | BY6: 95 | BZ6: 0 | CA6: 115 | CB6: 110 | CC6: 0 | CD6: 74 | CE6: 75 | CF6: 0 | CG6: 40 | CH6: 53 | CI6: 0 | CJ6: 20 | CK6: 44 | CL6: 0 | CM6: 8 | CN6: 9 | CO6: 0 | CP6: 0 | CQ6: 0 | CR6: 0
B7: Cabecera municipal | C7: 2024 | D7: 1129 | E7: 895 | F7: 0 | G7: 1 | H7: 2 | I7: 0 | J7: 15 | K7: 12 | L7: 0 | M7: 33 | N7: 23 | O7: 0 | P7: 19 | Q7: 24 | R7: 0 | S7: 0 | T7: 0 | U7: 0 | V7: 29 | W7: 37 | X7: 0 | Y7: 25 | Z7: 14 | AA7: 0 | AB7: 27 | AC7: 9 | AD7: 0 | AE7: 17 | AF7: 12 | AG7: 0 | AH7: 8 | AI7: 3 | AJ7: 0 | AK7: 7 | AL7: 13 | AM7: 0 | AN7: 35 | AO7: 15 | AP7: 0 | AQ7: 48 | AR7: 12 | AS7: 0 | AT7: 58 | AU7: 19 | AV7: 0 | AW7: 36 | AX7: 17 | AY7: 0 | AZ7: 44 | BA7: 29 | BB7: 0 | BC7: 33 | BD7: 36 | BE7: 0 | BF7: 39 | BG7: 24 | BH7: 0 | BI7: 50 | BJ7: 39 | BK7: 0 | BL7: 65 | BM7: 53 | BN7: 0 | BO7: 77 | BP7: 57 | BQ7: 0 | BR7: 98 | BS7: 67 | BT7: 0 | BU7: 83 | BV7: 58 | BW7: 0 | BX7: 76 | BY7: 77 | BZ7: 0 | CA7: 86 | CB7: 92 | CC7: 0 | CD7: 64 | CE7: 62 | CF7: 0 | CG7: 34 | CH7: 48 | CI7: 0 | CJ7: 17 | CK7: 35 | CL7: 0 | CM7: 5 | CN7: 6 | CO7: 0 | CP7: 0 | CQ7: 0 | CR7: 0
B8: Centro poblado | C8: 234 | D8: 139 | E8: 95 | F8: 0 | G8: 0 | H8: 1 | I8: 0 | J8: 5 | K8: 1 | L8: 0 | M8: 1 | N8: 3 | O8: 0 | P8: 0 | Q8: 2 | R8: 0 | S8: 0 | T8: 0 | U8: 0 | V8: 2 | W8: 2 | X8: 0 | Y8: 3 | Z8: 2 | AA8: 0 | AB8: 3 | AC8: 3 | AD8: 0 | AE8: 4 | AF8: 2 | AG8: 0 | AH8: 3 | AI8: 3 | AJ8: 0 | AK8: 2 | AL8: 2 | AM8: 0 | AN8: 5 | AO8: 2 | AP8: 0 | AQ8: 4 | AR8: 2 | AS8: 0 | AT8: 6 | AU8: 1 | AV8: 0 | AW8: 6 | AX8: 4 | AY8: 0 | AZ8: 4 | BA8: 4 | BB8: 0 | BC8: 8 | BD8: 4 | BE8: 0 | BF8: 4 | BG8: 2 | BH8: 0 | BI8: 7 | BJ8: 7 | BK8: 0 | BL8: 11 | BM8: 3 | BN8: 0 | BO8: 7 | BP8: 5 | BQ8: 0 | BR8: 6 | BS8: 4 | BT8: 0 | BU8: 6 | BV8: 7 | BW8: 0 | BX8: 13 | BY8: 6 | BZ8: 0 | CA8: 16 | CB8: 7 | CC8: 0 | CD8: 6 | CE8: 8 | CF8: 0 | CG8: 5 | CH8: 4 | CI8: 0 | CJ8: 1 | CK8: 3 | CL8: 0 | CM8: 1 | CN8: 1 | CO8: 0 | CP8: 0 | CQ8: 0 | CR8: 0
B9: Rural disperso | C9: 495 | D9: 272 | E9: 223 | F9: 0 | G9: 1 | H9: 2 | I9: 0 | J9: 14 | K9: 5 | L9: 0 | M9: 15 | N9: 7 | O9: 0 | P9: 9 | Q9: 9 | R9: 0 | S9: 0 | T9: 0 | U9: 0 | V9: 21 | W9: 24 | X9: 0 | Y9: 23 | Z9: 13 | AA9: 0 | AB9: 13 | AC9: 16 | AD9: 0 | AE9: 12 | AF9: 14 | AG9: 0 | AH9: 9 | AI9: 4 | AJ9: 0 | AK9: 3 | AL9: 3 | AM9: 0 | AN9: 7 | AO9: 8 | AP9: 0 | AQ9: 15 | AR9: 4 | AS9: 0 | AT9: 4 | AU9: 5 | AV9: 0 | AW9: 11 | AX9: 8 | AY9: 0 | AZ9: 12 | BA9: 4 | BB9: 0 | BC9: 7 | BD9: 3 | BE9: 0 | BF9: 12 | BG9: 8 | BH9: 0 | BI9: 7 | BJ9: 8 | BK9: 0 | BL9: 9 | BM9: 12 | BN9: 0 | BO9: 9 | BP9: 8 | BQ9: 0 | BR9: 8 | BS9: 13 | BT9: 0 | BU9: 14 | BV9: 8 | BW9: 0 | BX9: 15 | BY9: 12 | BZ9: 0 | CA9: 13 | CB9: 11 | CC9: 0 | CD9: 4 | CE9: 5 | CF9: 0 | CG9: 1 | CH9: 1 | CI9: 0 | CJ9: 2 | CK9: 6 | CL9: 0 | CM9: 2 | CN9: 2 | CO9: 0 | CP9: 0 | CQ9: 0 | CR9: 0
B10: Sin información | C10: 6 | D10: 6 | E10: 0 | F10: 0 | G10: 0 | H10: 0 | I10: 0 | J10: 0 | K10: 0 | L10: 0 | M10: 0 | N10: 0 | O10: 0 | P10: 0 | Q10: 0 | R10: 0 | S10: 0 | T10: 0 | U10: 0 | V10: 0 | W10: 0 | X10: 0 | Y10: 0 | Z10: 0 | AA10: 0 | AB10: 0 | AC10: 0 | AD10: 0 | AE10: 0 | AF10: 0 | AG10: 0 | AH10: 0 | AI10: 0 | AJ10: 0 | AK10: 0 | AL10: 0 | AM10: 0 | AN10: 0 | AO10: 0 | AP10: 0 | AQ10: 0 | AR10: 0 | AS10: 0 | AT10: 2 | AU10: 0 | AV10: 0 | AW10: 2 | AX10: 0 | AY10: 0 | AZ10: 0 | BA10: 0 | BB10: 0 | BC10: 1 | BD10: 0 | BE10: 0 | BF10: 1 | BG10: 0 | BH10: 0 | BI10: 0 | BJ10: 0 | BK10: 0 | BL10: 0 | BM10: 0 | BN10: 0 | BO10: 0 | BP10: 0 | BQ10: 0 | BR10: 0 | BS10: 0 | BT10: 0 | BU10: 0 | BV10: 0 | BW10: 0 | BX10: 0 | BY10: 0 | BZ10: 0 | CA10: 0 | CB10: 0 | CC10: 0 | CD10: 0 | CE10: 0 | CF10: 0 | CG10: 0 | CH10: 0 | CI10: 0 | CJ10: 0 | CK10: 0 | CL10: 0 | CM10: 0 | CN10: 0 | CO10: 0 | CP10: 0 | CQ10: 0 | CR10: 0
A11: 44001 Riohacha | B11: TOTAL | C11: 856 | D11: 498 | E11: 358 | F11: 0 | G11: 1 | H11: 2 | I11: 0 | J11: 17 | K11: 3 | L11: 0 | M11: 24 | N11: 10 | O11: 0 | P11: 12 | Q11: 8 | R11: 0 | S11: 0 | T11: 0 | U11: 0 | V11: 16 | W11: 17 | X11: 0 | Y11: 12 | Z11: 7 | AA11: 0 | AB11: 19 | AC11: 5 | AD11: 0 | AE11: 11 | AF11: 9 | AG11: 0 | AH11: 5 | AI11: 2 | AJ11: 0 | AK11: 5 | AL11: 4 | AM11: 0 | AN11: 18 | AO11: 9 | AP11: 0 | AQ11: 25 | AR11: 4 | AS11: 0 | AT11: 18 | AU11: 7 | AV11: 0 | AW11: 11 | AX11: 10 | AY11: 0 | AZ11: 19 | BA11: 10 | BB11: 0 | BC11: 11 | BD11: 9 | BE11: 0 | BF11: 17 | BG11: 11 | BH11: 0 | BI11: 21 | BJ11: 13 | BK11: 0 | BL11: 28 | BM11: 22 | BN11: 0 | BO11: 32 | BP11: 24 | BQ11: 0 | BR11: 34 | BS11: 34 | BT11: 0 | BU11: 32 | BV11: 26 | BW11: 0 | BX11: 34 | BY11: 34 | BZ11: 0 | CA11: 35 | CB11: 29 | CC11: 0 | CD11: 19 | CE11: 18 | CF11: 0 | CG11: 13 | CH11: 19 | CI11: 0 | CJ11: 6 | CK11: 10 | CL11: 0 | CM11: 3 | CN11: 2 | CO11: 0 | CP11: 0 | CQ11: 0 | CR11: 0
B12: Cabecera municipal | C12: 658 | D12: 390 | E12: 268 | F12: 0 | G12: 0 | H12: 1 | I12: 0 | J12: 9 | K12: 0 | L12: 0 | M12: 16 | N12: 6 | O12: 0 | P12: 8 | Q12: 5 | R12: 0 | S12: 0 | T12: 0 | U12: 0 | V12: 10 | W12: 9 | X12: 0 | Y12: 4 | Z12: 1 | AA12: 0 | AB12: 10 | AC12: 0 | AD12: 0 | AE12: 5 | AF12: 1 | AG12: 0 | AH12: 4 | AI12: 1 | AJ12: 0 | AK12: 2 | AL12: 4 | AM12: 0 | AN12: 15 | AO12: 6 | AP12: 0 | AQ12: 19 | AR12: 2 | AS12: 0 | AT12: 17 | AU12: 6 | AV12: 0 | AW12: 9 | AX12: 6 | AY12: 0 | AZ12: 18 | BA12: 8 | BB12: 0 | BC12: 7 | BD12: 8 | BE12: 0 | BF12: 15 | BG12: 9 | BH12: 0 | BI12: 20 | BJ12: 10 | BK12: 0 | BL12: 21 | BM12: 16 | BN12: 0 | BO12: 29 | BP12: 21 | BQ12: 0 | BR12: 31 | BS12: 30 | BT12: 0 | BU12: 29 | BV12: 21 | BW12: 0 | BX12: 25 | BY12: 30 | BZ12: 0 | CA12: 31 | CB12: 24 | CC12: 0 | CD12: 17 | CE12: 15 | CF12: 0 | CG12: 12 | CH12: 18 | CI12: 0 | CJ12: 6 | CK12: 9 | CL12: 0 | CM12: 1 | CN12: 1 | CO12: 0 | CP12: 0 | CQ12: 0 | CR12: 0
B13: Centro poblado | C13: 60 | D13: 37 | E13: 23 | F13: 0 | G13: 0 | H13: 1 | I13: 0 | J13: 3 | K13: 0 | L13: 0 | M13: 0 | N13: 1 | O13: 0 | P13: 0 | Q13: 0 | R13: 0 | S13: 0 | T13: 0 | U13: 0 | V13: 1 | W13: 0 | X13: 0 | Y13: 0 | Z13: 1 | AA13: 0 | AB13: 2 | AC13: 1 | AD13: 0 | AE13: 3 | AF13: 1 | AG13: 0 | AH13: 0 | AI13: 0 | AJ13: 0 | AK13: 2 | AL13: 0 | AM13: 0 | AN13: 2 | AO13: 0 | AP13: 0 | AQ13: 2 | AR13: 1 | AS13: 0 | AT13: 1 | AU13: 0 | AV13: 0 | AW13: 1 | AX13: 1 | AY13: 0 | AZ13: 1 | BA13: 2 | BB13: 0 | BC13: 2 | BD13: 1 | BE13: 0 | BF13: 0 | BG13: 0 | BH13: 0 | BI13: 1 | BJ13: 2 | BK13: 0 | BL13: 4 | BM13: 0 | BN13: 0 | BO13: 2 | BP13: 2 | BQ13: 0 | BR13: 2 | BS13: 0 | BT13: 0 | BU13: 1 | BV13: 3 | BW13: 0 | BX13: 4 | BY13: 0 | BZ13: 0 | CA13: 2 | CB13: 2 | CC13: 0 | CD13: 0 | CE13: 2 | CF13: 0 | CG13: 1 | CH13: 1 | CI13: 0 | CJ13: 0 | CK13: 1 | CL13: 0 | CM13: 0 | CN13: 0 | CO13: 0 | CP13: 0 | CQ13: 0 | CR13: 0
B14: Rural disperso | C14: 138 | D14: 71 | E14: 67 | F14: 0 | G14: 1 | H14: 0 | I14: 0 | J14: 5 | K14: 3 | L14: 0 | M14: 8 | N14: 3 | O14: 0 | P14: 4 | Q14: 3 | R14: 0 | S14: 0 | T14: 0 | U14: 0 | V14: 5 | W14: 8 | X14: 0 | Y14: 8 | Z14: 5 | AA14: 0 | AB14: 7 | AC14: 4 | AD14: 0 | AE14: 3 | AF14: 7 | AG14: 0 | AH14: 1 | AI14: 1 | AJ14: 0 | AK14: 1 | AL14: 0 | AM14: 0 | AN14: 1 | AO14: 3 | AP14: 0 | AQ14: 4 | AR14: 1 | AS14: 0 | AT14: 0 | AU14: 1 | AV14: 0 | AW14: 1 | AX14: 3 | AY14: 0 | AZ14: 0 | BA14: 0 | BB14: 0 | BC14: 2 | BD14: 0 | BE14: 0 | BF14: 2 | BG14: 2 | BH14: 0 | BI14: 0 | BJ14: 1 | BK14: 0 | BL14: 3 | BM14: 6 | BN14: 0 | BO14: 1 | BP14: 1 | BQ14: 0 | BR14: 1 | BS14: 4 | BT14: 0 | BU14: 2 | BV14: 2 | BW14: 0 | BX14: 5 | BY14: 4 | BZ14: 0 | CA14: 2 | CB14: 3 | CC14: 0 | CD14: 2 | CE14: 1 | CF14: 0 | CG14: 0 | CH14: 0 | CI14: 0 | CJ14: 0 | CK14: 0 | CL14: 0 | CM14: 2 | CN14: 1 | CO14: 0 | CP14: 0 | CQ14: 0 | CR14: 0
B15: Sin información | C15: 0 | D15: 0 | E15: 0 | F15: 0 | G15: 0 | H15: 0 | I15: 0 | J15: 0 | K15: 0 | L15: 0 | M15: 0 | N15: 0 | O15: 0 | P15: 0 | Q15: 0 | R15: 0 | S15: 0 | T15: 0 | U15: 0 | V15: 0 | W15: 0 | X15: 0 | Y15: 0 | Z15: 0 | AA15: 0 | AB15: 0 | AC15: 0 | AD15: 0 | AE15: 0 | AF15: 0 | AG15: 0 | AH15: 0 | AI15: 0 | AJ15: 0 | AK15: 0 | AL15: 0 | AM15: 0 | AN15: 0 | AO15: 0 | AP15: 0 | AQ15: 0 | AR15: 0 | AS15: 0 | AT15: 0 | AU15: 0 | AV15: 0 | AW15: 0 | AX15: 0 | AY15: 0 | AZ15: 0 | BA15: 0 | BB15: 0 | BC15: 0 | BD15: 0 | BE15: 0 | BF15: 0 | BG15: 0 | BH15: 0 | BI15: 0 | BJ15: 0 | BK15: 0 | BL15: 0 | BM15: 0 | BN15: 0 | BO15: 0 | BP15: 0 | BQ15: 0 | BR15: 0 | BS15: 0 | BT15: 0 | BU15: 0 | BV15: 0 | BW15: 0 | BX15: 0 | BY15: 0 | BZ15: 0 | CA15: 0 | CB15: 0 | CC15: 0 | CD15: 0 | CE15: 0 | CF15: 0 | CG15: 0 | CH15: 0 | CI15: 0 | CJ15: 0 | CK15: 0 | CL15: 0 | CM15: 0 | CN15: 0 | CO15: 0 | CP15: 0 | CQ15: 0 | CR15: 0
A17: Defunciones La Guajira | C17: =C6 -> 2759 | F17: Defunciones Guajira Hombres | I17: =D6 -> 1546
A18: Defunciones Riohacha | C18: =C11 -> 856 | F18: Defunciones Guajira Mujeres | I18: =E6 -> 1213
F20: Defunciones Hombres Riohacha | I20: =D11 -> 498
F21: Defunciones Mujeres Riohacha | I21: =E11 -> 358

Sheet TE2018
A1: Tasas Específicas de Mortalidad
I2: n | J2: 10000
M3: La Guajira
B4: La Guajira - Riohacha | G4: Riohacha | M4: Población Total | O4: 0 | P4: 1 a 4 | Q4: 5 a 9 | R4: 10 a 14 | S4: 15 a 19 | T4: 20 a 24 | U4: 25 a 29 | V4: 30 a 34 | W4: 35 a 39 | X4: 40 a 44 | Y4: 45 a 49 | Z4: 50 a 54 | AA4: 55 a 59 | AB4: 60 a 64 | AC4: 65 a 69 | AD4: 70 a 74 | AE4: 75 a 79 | AF4: 80 a 84 | AG4: 85 a 89 | AH4: 90 a 94 | AI4: 94 a 99 | AJ4: 100 o más
G5: Defunciones | H5: Población Total | I5: TEM | O5: =SUM(E6,E141,E269,E393,E525,E645,E769,E893,E1015,E1129,E1272,E1402,E1539,E1679,E1803) -> 17784 | P5: =SUM(E7:E10,E142:E145,E270:E273,E394:E397,E526:E529,E646:E649,E770:E773,E894:E897,E1016:E1019,E1130:E1133,E1273:E1276,E1403:E1406,E1540:E1543,E1680:E1683,E1804:E1807) -> 79680 | Q5: =SUM(E17,E152,E280,E404,E536,E656,E780,E904,E1026,E1140,E1283,E1413,E1550,E1690,E1814) -> 98818 | R5: =SUM(E23,E158,E286,E410,E542,E662,E786,E910,E1032,E1146,E1289,E1419,E1556,E1696,E1820) -> 90547 | S5: =SUM(E29,E164,E292,E416,E548,E668,E792,E916,E1038,E1152,E1295,E1425,E1562,E1702,E1826) -> 87425 | T5: =SUM(E35,E170,E298,E422,E554,E674,E798,E922,E1044,E1158,E1301,E1431,E1568,E1708,E1832) -> 77426 | U5: =SUM(E41,E176,E304,E428,E560,E680,E804,E928,E1050,E1164,E1307,E1437,E1574,E1714,E1838) -> 66200 | V5: =SUM(E47,E182,E310,E434,E566,E686,E810,E934,E1056,E1170,E1313,E1443,E1580,E1720,E1844) -> 58628 | W5: =SUM(E53,E188,E316,E440,E572,E692,E816,E940,E1062,E1176,E1319,E1449,E1586,E1726,E1850) -> 52083 | X5: =SUM(E59,E194,E322,E446,E578,E698,E822,E946,E1068,E1182,E1325,E1455,E1592,E1732,E1856) -> 41659 | Y5: =SUM(E65,E200,E328,E452,E584,E704,E828,E952,E1074,E1188,E1331,E1461,E1598,E1738,E1862) -> 35856 | Z5: =SUM(E71,E206,E334,E458,E590,E710,E834,E958,E1080,E1194,E1337,E1467,E1604,E1744,E1868) -> 31199 | AA5: =SUM(E77,E212,E340,E464,E596,E716,E840,E964,E1086,E1194,E1337,E1473,E1610,E1750,E1874) -> 28693 | AB5: =SUM(E83,E218,E346,E470,E602,E722,E846,E1092,E1206,E1349,E1479,E1616,E1756,E1880) -> 18965 | AC5: =SUM(E89,E224,E352,E476,E608,E728,E852,E976,E1098,E1212,E1355,E1485,E1622,E1762,E1886) -> 14884 | AD5: =SUM(E95,E230,E358,E482,E614,E734,E858,E982,E1104,E1218,E1361,E1491,E1628,E1768,E1892) -> 10026 | AE5: =SUM(E101,E236,E364,E488,E620,E740,E864,E988,E1110,E1224,E1367,E1497,E1634,E1774,E1898) -> 7352 | AF5: =SUM(E107,E242,E370,E494,E626,E746,E870,E994,E1116,E1230,E1373,E1503,E1640,E1780,E1904) -> 4340 | AG5: =SUM(E113,E248,E376,E500,E632,E752,E876,E1000,E1122,E1236,E1379,E1509,E1646,E1786,E1910) -> 2595 | AH5: =SUM(E119,E254,E382,E506,E638,E758,E882,E1005,E1126,E1242,E1385,E1515,E1652,E1792,E1916) -> 1184 | AI5: =SUM(E125,E259,E388,E511,E644,E764,E888,E1011,E1128,E1248,E1391,E1521,E1658,E1797,E1922) -> 510 | AJ5: =SUM(E131,E134,E138,E140,E262,E264,E266,E268,E516,E518,E521,E524,E892,E1014,E1254,E1259,E1264,E1268,E1271,E1395,E1399,E1401,E1526,E1529,E1534,E1536,E1538,E1664,E1669,E1673,E1676,E1678,E1800,E1802,E1925,E1927) -> 217
A6: 44_La Guajira | B6: 44001_Riohacha | C6: 0 a 4 | D6: 0 | E6: 3970 | G6: =SUM('DF2018'!G11:AA11) -> 129 | H6: =E6 -> 3970 | I6: =J2*G6/H6 -> 324.93703 | M6: =SUM('DF2018'!G6:AA6) -> 399 | N6: =O5 -> 17784 | O6: =J2*M6/N6 -> 224.35897
D7: 1 | E7: 4108 | G7: =SUM('DF2018'!AB11:AG11) -> 44 | H7: =SUM(E7:E10) -> 16486 | I7: =J2*G7/H7 -> 26.689312 | M7: =SUM('DF2018'!AB6:AG6) -> 132 | N7: =P5 -> 79680 | O7: =J2*M7/N7 -> 16.566265
D8: 2 | E8: 4216
D9: 3 | E9: 4207 | T9: GRÁFICOS
D10: 4 | E10: 3955
D11: Total grupo edad | E11: 20456
C12: 5 a 9 | D12: 5 | E12: 4051 | G12: =SUM('DF2018'!AH11:AJ11) -> 7 | H12: =E17 -> 20231 | I12: =J2*G12/H12 -> 3.4600366 | M12: =SUM('DF2018'!AH6:AJ6) -> 30 | N12: =Q5 -> 98818 | O12: =M12*J2/N12 -> 3.0358842
D13: 6 | E13: 4235
D14: 7 | E14: 4042
D15: 8 | E15: 3944
D16: 9 | E16: 3959
D17: Total grupo edad | E17: 20231
C18: 10 a 14 | D18: 10 | E18: 3849 | G18: =SUM('DF2018'!AK11:AM11) -> 9 | H18: =E23 -> 18438 | I18: =J2*G18/H18 -> 4.8812236 | M18: =SUM('DF2018'!AK6:AM6) -> 30 | N18: =R5 -> 90547 | O18: =M18*J2/N18 -> 3.3131965
D19: 11 | E19: 3874
D20: 12 | E20: 3576
D21: 13 | E21: 3631
D22: 14 | E22: 3508
D23: Total grupo edad | E23: 18438
C24: 15 a 19 | D24: 15 | E24: 3445 | G24: =SUM('DF2018'!AN11:AP11) -> 27 | H24: =E29 -> 17906 | I24: =J2*G24/H24 -> 15.078745 | M24: =SUM('DF2018'!AN6:AP6) -> 72 | N24: =S5 -> 87425 | O24: =J2*M24/N24 -> 8.2356305
D25: 16 | E25: 3358
D26: 17 | E26: 3599
D27: 18 | E27: 3959
D28: 19 | E28: 3545
D29: Total grupo edad | E29: 17906
C30: 20 a 24 | D30: 20 | E30: 3488 | G30: =SUM('DF2018'!AQ11:AS11) -> 29 | H30: =E35 -> 16823 | I30: =J2*G30/H30 -> 17.238305 | M30: =SUM('DF2018'!AQ6:AS6) -> 85 | N30: =T5 -> 77426 | O30: =M30*J2/N30 -> 10.978224
D31: 21 | E31: 3233
D32: 22 | E32: 3448
D33: 23 | E33: 3440
D34: 24 | E34: 3214
D35: Total grupo edad | E35: 16823
C36: 25 a 29 | D36: 25 | E36: 3226 | G36: =SUM('DF2018'!AT11:AV11) -> 25 | H36: =E41 -> 15035 | I36: =J2*G36/H36 -> 16.627868 | M36: =SUM('DF2018'!AT6:AV6) -> 95 | N36: =U5 -> 66200 | O36: =J2*M36/N36 -> 14.350453
D37: 26 | E37: 3105
D38: 27 | E38: 2945
D39: 28 | E39: 2863
D40: 29 | E40: 2896
...

Sheet Causas Mortalidad 2018
B2: TOTAL | C2: Total | H2: TOTAL | I2: Total | N2: La guajira | P2: Total | T2: Riohacha | V2: Total
C3: TOTAL | D3: Hombres | E3: Mujeres | I3: TOTAL | J3: Hombres | K3: Mujeres | P3: TOTAL | Q3: Hombres | R3: Mujeres | V3: TOTAL | W3: Hombres | X3: Mujeres
A4: TOTAL | B4: TOTAL | C4: 2759 | D4: 1546 | E4: 1213 | G4: TOTAL | H4: TOTAL | I4: 856 | J4: 498 | K4: 358 | N4: TOTAL | O4: TOTAL | P4: =C4 -> 2759 | Q4: =D4 -> 1546 | R4: =E4 -> 1213 | T4: TOTAL | U4: TOTAL | V4: =I4 -> 856 | W4: =J4 -> 498 | X4: =K4 -> 358
B5: 101 Enfermedades infecciosas intestinales | C5: 43 | D5: 27 | E5: 16 | H5: 101 Enfermedades infecciosas intestinales | I5: 10 | J5: 8 | K5: 2 | O5: 101 Enfermedades infecciosas intestinales | P5: =C5/$C$4 -> 0.015585357 | Q5: =D5/$D$4 -> 0.017464424 | R5: =E5/$E$4 -> 0.013190437 | U5: 101 Enfermedades infecciosas intestinales | V5: =I5/$I$4 -> 0.011682243 | W5: =J5/$J$4 -> 0.016064257 | X5: =K5/$K$4 -> 0.0055865922
B6: 102 Tuberculosis | C6: 50 | D6: 26 | E6: 24 | H6: 102 Tuberculosis | I6: 13 | J6: 7 | K6: 6 | O6: 102 Tuberculosis | P6: =C6/$C$4 -> 0.018122508 | Q6: =D6/$D$4 -> 0.016817594 | R6: =E6/$E$4 -> 0.019785655 | U6: 102 Tuberculosis | V6: =I6/$I$4 -> 0.015186916 | W6: =J6/$J$4 -> 0.014056225 | X6: =K6/$K$4 -> 0.016759777
B7: 103 Ciertas enfermedades transmisibles por vectores y rabia | C7: 8 | D7: 3 | E7: 5 | H7: 103 Ciertas enfermedades transmisibles por vectores y rabia | I7: 7 | J7: 2 | K7: 5 | O7: 103 Ciertas enfermedades transmisibles por vectores y rabia | P7: =C7/$C$4 -> 0.0028996013 | Q7: =D7/$D$4 -> 0.0019404916 | R7: =E7/$E$4 -> 0.0041220115 | U7: 103 Ciertas enfermedades transmisibles por vectores y rabia | V7: =I7/$I$4 -> 0.0081775701 | W7: =J7/$J$4 -> 0.0040160643 | X7: =K7/$K$4 -> 0.01396648
B8: 104 Ciertas enfermedades inmunoprevenibles | C8: 2 | D8: 2 | E8: 0 | H8: 104 Ciertas enfermedades inmunoprevenibles | I8: 1 | J8: 1 | K8: 0 | O8: 104 Ciertas enfermedades inmunoprevenibles | P8: =C8/$C$4 -> 0.00072490033 | Q8: =D8/$D$4 -> 0.0012936611 | R8: =E8/$E$4 -> 0 | U8: 104 Ciertas enfermedades inmunoprevenibles | V8: =I8/$I$4 -> 0.0011682243 | W8: =J8/$J$4 -> 0.0020080321 | X8: =K8/$K$4 -> 0
B9: 105 Meningitis | C9: 13 | D9: 7 | E9: 6 | H9: 105 Meningitis | I9: 4 | J9: 2 | K9: 2 | O9: 105 Meningitis | P9: =C9/$C$4 -> 0.0047118521 | Q9: =D9/$D$4 -> 0.0045278137 | R9: =E9/$E$4 -> 0.0049464138 | U9: 105 Meningitis | V9: =I9/$I$4 -> 0.0046728972 | W9: =J9/$J$4 -> 0.0040160643 | X9: =K9/$K$4 -> 0.0055865922
B10: 106 Septicemia, excepto neonatal | C10: 23 | D10: 13 | E10: 10 | H10: 106 Septicemia, excepto neonatal | I10: 13 | J10: 5 | K10: 8 | O10: 106 Septicemia, excepto neonatal | P10: =C10/$C$4 -> 0.0083363538 | Q10: =D10/$D$4 -> 0.0084087969 | R10: =E10/$E$4 -> 0.0082440231 | U10: 106 Septicemia, excepto neonatal | V10: =I10/$I$4 -> 0.015186916 | W10: =J10/$J$4 -> 0.010040161 | X10: =K10/$K$4 -> 0.022346369
B11: 107 Enfermedad por el VIH (SIDA) | C11: 41 | D11: 26 | E11: 15 | H11: 107 Enfermedad por el VIH (SIDA) | I11: 14 | J11: 8 | K11: 6 | O11: 107 Enfermedad por el VIH (SIDA) | P11: =C11/$C$4 -> 0.014860457 | Q11: =D11/$D$4 -> 0.016817594 | R11: =E11/$E$4 -> 0.012366035 | U11: 107 Enfermedad por el VIH (SIDA) | V11: =I11/$I$4 -> 0.01635514 | W11: =J11/$J$4 -> 0.016064257 | X11: =K11/$K$4 -> 0.016759777
A12: La guajira | B12: 108 Infecciones respiratorias agudas | C12: 187 | D12: 99 | E12: 88 | G12: Riohacha | H12: 108 Infecciones respiratorias agudas | I12: 61 | J12: 29 | K12: 32 | O12: 108 Infecciones respiratorias agudas | P12: =C12/$C$4 -> 0.067778181 | Q12: =D12/$D$4 -> 0.064036223 | R12: =E12/$E$4 -> 0.072547403 | U12: 108 Infecciones respiratorias agudas | V12: =I12/$I$4 -> 0.071261682 | W12: =J12/$J$4 -> 0.058232932 | X12: =K12/$K$4 -> 0.089385475
B13: 109 Resto de ciertas enfermedades infecciosas y parasitarias | C13: 23 | D13: 10 | E13: 13 | H13: 109 Resto de ciertas enfermedades infecciosas y parasitarias | I13: 9 | J13: 5 | K13: 4 | O13: 109 Resto de ciertas enfermedades infecciosas y parasitarias | P13: =C13/$C$4 -> 0.0083363538 | Q13: =D13/$D$4 -> 0.0064683053 | R13: =E13/$E$4 -> 0.01071723 | U13: 109 Resto de ciertas enfermedades infecciosas y parasitarias | V13: =I13/$I$4 -> 0.010514019 | W13: =J13/$J$4 -> 0.010040161 | X13: =K13/$K$4 -> 0.011173184
B14: 201 Tumor maligno del estómago | C14: 26 | D14: 19 | E14: 7 | H14: 201 Tumor maligno del estómago | I14: 8 | J14: 4 | K14: 4 | O14: 201 Tumor maligno del estómago | P14: =C14/$C$4 -> 0.0094237042 | Q14: =D14/$D$4 -> 0.01228978 | R14: =E14/$E$4 -> 0.0057708162 | U14: 201 Tumor maligno del estómago | V14: =I14/$I$4 -> 0.0093457944 | W14: =J14/$J$4 -> 0.0080321285 | X14: =K14/$K$4 -> 0.011173184
B15: 202 Tumor maligno del colon y de la unión rectosigmoidea | C15: 14 | D15: 9 | E15: 5 | H15: 202 Tumor maligno del colon y de la unión rectosigmoidea | I15: 3 | J15: 2 | K15: 1 | O15: 202 Tumor maligno del colon y de la unión rectosigmoidea | P15: =C15/$C$4 -> 0.0050743023 | Q15: =D15/$D$4 -> 0.0058214748 | R15: =E15/$E$4 -> 0.0041220115 | U15: 202 Tumor maligno del colon y de la unión rectosigmoidea | V15: =I15/$I$4 -> 0.0035046729 | W15: =J15/$J$4 -> 0.0040160643 | X15: =K15/$K$4 -> 0.0027932961
B16: 203 Tumor maligno de los órganos digestivos y del peritoneo excepto estómago y colon | C16: 52 | D16: 23 | E16: 29 | H16: 203 Tumor maligno de los órganos digestivos y del peritoneo excepto estómago y colon | I16: 21 | J16: 10 | K16: 11 | O16: 203 Tumor maligno de los órganos digestivos y del peritoneo excepto estómago y colon | P16: =C16/$C$4 -> 0.018847408 | Q16: =D16/$D$4 -> 0.014877102 | R16: =E16/$E$4 -> 0.023907667 | U16: 203 Tumor maligno de los órganos digestivos y del peritoneo excepto estómago y colon | V16: =I16/$I$4 -> 0.02453271 | W16: =J16/$J$4 -> 0.020080321 | X16: =K16/$K$4 -> 0.030726257
B17: 204 Tumor maligno de la tráquea, los bronquios y el pulmón | C17: 48 | D17: 26 | E17: 22 | H17: 204 Tumor maligno de la tráquea, los bronquios y el pulmón | I17: 16 | J17: 8 | K17: 8 | O17: 204 Tumor maligno de la tráquea, los bronquios y el pulmón | P17: =C17/$C$4 -> 0.017397608 | Q17: =D17/$D$4 -> 0.016817594 | R17: =E17/$E$4 -> 0.018136851 | U17: 204 Tumor maligno de la tráquea, los bronquios y el pulmón | V17: =I17/$I$4 -> 0.018691589 | W17: =J17/$J$4 -> 0.016064257 | X17: =K17/$K$4 -> 0.022346369
B18: 205 Tumor maligno de los órganos respiratorios e intratorácicos, excepto tráquea, bronquios y pulmón | C18: 6 | D18: 4 | E18: 2 | H18: 205 Tumor maligno de los órganos respiratorios e intratorácicos, excepto tráquea, bronquios y pulmón | I18: 2 | J18: 2 | K18: 0 | O18: 205 Tumor maligno de los órganos respiratorios e intratorácicos, excepto tráquea, bronquios y pulmón | P18: =C18/$C$4 -> 0.002174701 | Q18: =D18/$D$4 -> 0.0025873221 | R18: =E18/$E$4 -> 0.0016488046 | U18: 205 Tumor maligno de los órganos respiratorios e intratorácicos, excepto tráquea, bronquios y pulmón | V18: =I18/$I$4 -> 0.0023364486 | W18: =J18/$J$4 -> 0.0040160643 | X18: =K18/$K$4 -> 0
B19: 206 Tumor maligno de la mama de la mujer | C19: 34 | D19: 0 | E19: 34 | H19: 206 Tumor maligno de la mama de la mujer | I19: 10 | J19: 0 | K19: 10 | O19: 206 Tumor maligno de la mama de la mujer | P19: =C19/$C$4 -> 0.012323306 | Q19: =D19/$D$4 -> 0 | R19: =E19/$E$4 -> 0.028029678 | U19: 206 Tumor maligno de la mama de la mujer | V19: =I19/$I$4 -> 0.011682243 | W19: =J19/$J$4 -> 0 | X19: =K19/$K$4 -> 0.027932961
B20: 207 Tumor maligno del cuello del útero | C20: 30 | D20: 0 | E20: 30 | H20: 207 Tumor maligno del cuello del útero | I20: 9 | J20: 0 | K20: 9 | O20: 207 Tumor maligno del cuello del útero | P20: =C20/$C$4 -> 0.010873505 | Q20: =D20/$D$4 -> 0 | R20: =E20/$E$4 -> 0.024732069 | U20: 207 Tumor maligno del cuello del útero | V20: =I20/$I$4 -> 0.010514019 | W20: =J20/$J$4 -> 0 | X20: =K20/$K$4 -> 0.025139665
B21: 209 Tumor maligno del útero, parte no especificada | C21: 2 | D21: 0 | E21: 2 | H21: 209 Tumor maligno del útero, parte no especificada | I21: 1 | J21: 0 | K21: 1 | O21: 209 Tumor maligno del útero, parte no especificada | P21: =C21/$C$4 -> 0.00072490033 | Q21: =D21/$D$4 -> 0 | R21: =E21/$E$4 -> 0.0016488046 | U21: 209 Tumor maligno del útero, parte no especificada | V21: =I21/$I$4 -> 0.0011682243 | W21: =J21/$J$4 -> 0 | X21: =K21/$K$4 -> 0.0027932961
B22: 210 Tumor maligno de la próstata | C22: 47 | D22: 47 | E22: 0 | H22: 210 Tumor maligno de la próstata | I22: 13 | J22: 13 | K22: 0 | O22: 210 Tumor maligno de la próstata | P22: =C22/$C$4 -> 0.017035158 | Q22: =D22/$D$4 -> 0.030401035 | R22: =E22/$E$4 -> 0 | U22: 210 Tumor maligno de la próstata | V22: =I22/$I$4 -> 0.015186916 | W22: =J22/$J$4 -> 0.026104418 | X22: =K22/$K$4 -> 0
B23: 211 Tumor maligno de otros órganos genitourinarios | C23: 13 | D23: 3 | E23: 10 | H23: 211 Tumor maligno de otros órganos genitourinarios | I23: 4 | J23: 0 | K23: 4 | O23: 211 Tumor maligno de otros órganos genitourinarios | P23: =C23/$C$4 -> 0.0047118521 | Q23: =D23/$D$4 -> 0.0019404916 | R23: =E23/$E$4 -> 0.0082440231 | U23: 211 Tumor maligno de otros órganos genitourinarios | V23: =I23/$I$4 -> 0.0046728972 | W23: =J23/$J$4 -> 0 | X23: =K23/$K$4 -> 0.011173184
B24: 212 Leucemia | C24: 19 | D24: 9 | E24: 10 | H24: 212 Leucemia | I24: 7 | J24: 4 | K24: 3 | O24: 212 Leucemia | P24: =C24/$C$4 -> 0.0068865531 | Q24: =D24/$D$4 -> 0.0058214748 | R24: =E24/$E$4 -> 0.0082440231 | U24: 212 Leucemia | V24: =I24/$I$4 -> 0.0081775701 | W24: =J24/$J$4 -> 0.0080321285 | X24: =K24/$K$4 -> 0.0083798883
... B63: 612 Embarazo, parto y puerperio | C63: 25 | D63: 0 | E63: 25 | H63: 700 Signos, síntomas y afecciones mal definidas | I63: 38 | J63: 21 | K63: 17 | O63: 612 Embarazo, parto y puerperio | P63: =C63/$C$4 -> 0.0090612541 | Q63: =D63/$D$4 -> 0 | R63: =E63/$E$4 -> 0.020610058 | U63: 700 Signos, síntomas y afecciones mal definidas | V63: =I63/$I$4 -> 0.044392523 | W63: =J63/$J$4 -> 0.042168675 | X63: =K63/$K$4 -> 0.047486034
B64: 613 Malformaciones congénitas, deformidades y anomalías cromosómicas | C64: 71 | D64: 36 | E64: 35 | O64: 613 Malformaciones congénitas, deformidades y anomalías cromosómicas | P64: =C64/$C$4 -> 0.025733962 | Q64: =D64/$D$4 -> 0.023285899 | R64: =E64/$E$4 -> 0.028854081
B65: 614 Resto de las enfermedades | C65: 68 | D65: 33 | E65: 35 | O65: 614 Resto de las enfermedades | P65: =C65/$C$4 -> 0.024646611 | Q65: =D65/$D$4 -> 0.021345408 | R65: =E65/$E$4 -> 0.028854081
B66: 700 Signos, síntomas y afecciones mal definidas | C66: 88 | D66: 51 | E66: 37 | O66: 700 Signos, síntomas y afecciones mal definidas | P66: =C66/$C$4 -> 0.031895614 | Q66: =D66/$D$4 -> 0.032988357 | R66: =E66/$E$4 -> 0.030502885

Sheet Causas Mortalidad 2005
A1: Lugar de Ocurrencia Mortalidad por Causa La Guajira
A3: Causas de Muerte en La Guajira | B3: TOTAL
B4: TOTAL | C4: Hombres | D4: Mujeres
A5: TOTAL | B5: 475 | C5: 409 | D5: 66 | G5: Total | H5: Hombres | I5: Mujeres
A6: 501 ACC. TRANSPORTE TERRESTRE, INCLUSIVE SECUELAS | B6: 81 | C6: 54 | D6: 27 | F6: 501 ACC. TRANSPORTE TERRESTRE, INCLUSIVE SECUELAS | G6: =B6/B5 -> 0.17052632 | H6: =C6/$C$5 -> 0.13202934 | I6: =D6/$D$5 -> 0.40909091
A7: 502 OTROS ACC. TRANSPORTE Y LOS NO ESP., INCLUSIVE SECUELAS | B7: 1 | C7: 1 | F7: 502 OTROS ACC. TRANSPORTE Y LOS NO ESP., INCLUSIVE SECUELAS | G7: =B7/$B$5 -> 0.0021052632 | H7: =C7/$C$5 -> 0.0024449878
A8: 503 CAIDAS | B8: 1 | C8: 1 | F8: 503 CAIDAS | G8: =B8/$B$5 -> 0.0021052632 | H8: =C8/$C$5 -> 0.0024449878
A9: 505 ACC. CAUSADOS POR DISPARO DE ARMAS DE FUEGO | B9: 1 | C9: 1 | F9: 505 ACC. CAUSADOS POR DISPARO DE ARMAS DE FUEGO | G9: =B9/$B$5 -> 0.0021052632 | H9: =C9/$C$5 -> 0.0024449878
A10: 506 AHOGAMIENTO Y SUMERSION ACCIDENTALES | B10: 10 | C10: 10 | F10: 506 AHOGAMIENTO Y SUMERSION ACCIDENTALES | G10: =B10/$B$5 -> 0.021052632 | H10: =C10/$C$5 -> 0.024449878
A11: 507 EXPOSICION AL HUMO, FUEGO Y LLAMAS | B11: 2 | C11: 1 | D11: 1 | F11: 507 EXPOSICION AL HUMO, FUEGO Y LLAMAS | G11: =B11/$B$5 -> 0.0042105263 | H11: =C11/$C$5 -> 0.0024449878 | I11: =D11/$D$5 -> 0.015151515
A12: 508 ENVENENAMIENTO. ACC. POR, Y EXPOSICION A SUSTANC.NOCIVAS | B12: 1 | D12: 1 | F12: 508 ENVENENAMIENTO. ACC. POR, Y EXPOSICION A SUSTANC.NOCIVAS | G12: =B12/$B$5 -> 0.0021052632 | I12: =D12/$D$5 -> 0.015151515
A13: 510 OTROS ACCIDENTES, INCLUSIVE SECUELAS | B13: 25 | C13: 20 | D13: 5 | F13: 510 OTROS ACCIDENTES, INCLUSIVE SECUELAS | G13: =B13/$B$5 -> 0.052631579 | H13: =C13/$C$5 -> 0.048899756 | I13: =D13/$D$5 -> 0.075757576
A14: 511 LESIONES AUTOINFLIGIDAS INTENC.(SUICIDIOS), INCL. SECUELAS | B14: 15 | C14: 13 | D14: 2 | F14: 511 LESIONES AUTOINFLIGIDAS INTENC.(SUICIDIOS), INCL. SECUELAS | G14: =B14/$B$5 -> 0.031578947 | H14: =C14/$C$5 -> 0.031784841 | I14: =D14/$D$5 -> 0.03030303
A15: 512 AGRESIONES (HOMICIDIOS), INCLUSIVE SECUELAS | B15: 335 | C15: 306 | D15: 29 | F15: 512 AGRESIONES (HOMICIDIOS), INCLUSIVE SECUELAS | G15: =B15/$B$5 -> 0.70526316 | H15: =C15/$C$5 -> 0.74816626 | I15: =D15/$D$5 -> 0.43939394
A16: 514 EVENTOS DE INTENCION NO DETERMINADA, INCL. SECUELAS | B16: 3 | C16: 2 | D16: 1 | F16: 514 EVENTOS DE INTENCION NO DETERMINADA, INCL. SECUELAS | G16: =B16/$B$5 -> 0.0063157895 | H16: =C16/$C$5 -> 0.0048899756 | I16: =D16/$D$5 -> 0.015151515
G17: =SUM(G6:G16) -> 1 | H17: =SUM(H6:H16) -> 1 | I17: =SUM(I6:I16) -> 1
A22: Lugar de Ocurrencia Mortalidad por Causa Riohacha
A25: LISTA 6/67 CIE 10 DE OPS | B25: TOTAL | C25: TOTAL
C26: Hombres | D26: Mujeres | F26: TOTAL | G26: TOTAL | H26: Hombres | I26: Mujeres
A27: TOTAL | B27: 147 | C27: 129 | D27: 18
A28: 501 ACC. TRANSPORTE TERRESTRE, INCLUSIVE SECUELAS | B28: 34 | C28: 24 | D28: 10 | F28: 501 ACC. TRANSPORTE TERRESTRE, INCLUSIVE SECUELAS | G28: =B28/$B$27 -> 0.23129252 | H28: =C28/$C$27 -> 0.18604651 | I28: =D28/$D$27 -> 0.55555556
A29: 503 CAIDAS | B29: 1 | C29: 1 | D29: . | F29: 503 CAIDAS | G29: =B29/$B$27 -> 0.0068027211 | H29: =C29/$C$27 -> 0.007751938
A30: 506 AHOGAMIENTO Y SUMERSION ACCIDENTALES | B30: 2 | C30: 2 | D30: . | F30: 506 AHOGAMIENTO Y SUMERSION ACCIDENTALES | G30: =B30/$B$27 -> 0.013605442 | H30: =C30/$C$27 -> 0.015503876
A31: 507 EXPOSICION AL HUMO, FUEGO Y LLAMAS | B31: 1 | C31: 1 | D31: . | F31: 507 EXPOSICION AL HUMO, FUEGO Y LLAMAS | G31: =B31/$B$27 -> 0.0068027211 | H31: =C31/$C$27 -> 0.007751938
A32: 510 OTROS ACCIDENTES, INCLUSIVE SECUELAS | B32: 5 | C32: 4 | D32: 1 | F32: 510 OTROS ACCIDENTES, INCLUSIVE SECUELAS | G32: =B32/$B$27 -> 0.034013605 | H32: =C32/$C$27 -> 0.031007752 | I32: =D32/$D$27 -> 0.055555556
A33: 511 LESIONES AUTOINFLIGIDAS INTENC.(SUICIDIOS), INCL. SECUELAS | B33: 3 | C33: 2 | D33: 1 | F33: 511 LESIONES AUTOINFLIGIDAS INTENC.(SUICIDIOS), INCL. SECUELAS | G33: =B33/$B$27 -> 0.020408163 | H33: =C33/$C$27 -> 0.015503876 | I33: =D33/$D$27 -> 0.055555556
A34: 512 AGRESIONES (HOMICIDIOS), INCLUSIVE SECUELAS | B34: 99 | C34: 94 | D34: 5 | F34: 512 AGRESIONES (HOMICIDIOS), INCLUSIVE SECUELAS | G34: =B34/$B$27 -> 0.67346939 | H34: =C34/$C$27 -> 0.72868217 | I34: =D34/$D$27 -> 0.27777778
A35: 514 EVENTOS DE INTENCION NO DETERMINADA, INCL. SECUELAS | B35: 2 | C35: 1 | D35: 1 | F35: 514 EVENTOS DE INTENCION NO DETERMINADA, INCL. SECUELAS | G35: =B35/$B$27 -> 0.013605442 | H35: =C35/$C$27 -> 0.007751938 | I35: =D35/$D$27 -> 0.055555556
G36: =SUM(G28:G35) -> 1 | H36: =SUM(H28:H35) -> 1 | I36: =SUM(I28:I35) -> 1

Sheet Causas Mortalidad 2005 Residenc
A2: La Guajira | B2: TOTAL | C2: TOTAL | G2: LA GUAJIRA
C3: Hombres | D3: Mujeres | I3: TOTAL
A4: TOTAL | B4: 1692 | C4: 1015 | D4: 677 | G4: TOTAL | H4: TOTAL | I4: Hombres | J4: Mujeres
A5: 101 ENFERMEDADES INFECCIOSAS INTESTINALES | B5: 39 | C5: 16 | D5: 23 | G5: 101 ENFERMEDADES INFECCIOSAS INTESTINALES | H5: =B5/$B$4 -> 0.023049645 | I5: =C5/$C$4 -> 0.015763547 | J5: =D5/$D$4 -> 0.033973412
A6: 102 TUBERCULOSIS, INCLUSIVE SECUELAS | B6: 19 | C6: 6 | D6: 13 | G6: 102 TUBERCULOSIS, INCLUSIVE SECUELAS | H6: =B6/$B$4 -> 0.011229314 | I6: =C6/$C$4 -> 0.00591133 | J6: =D6/$D$4 -> 0.019202363
A7: 103 CIERTAS ENF. TRANSMITIDAS POR VECTORES Y RABIA | B7: 1 | C7: 1 | G7: 103 CIERTAS ENF. TRANSMITIDAS POR VECTORES Y RABIA | H7: =B7/$B$4 -> 0.00059101655 | I7: =C7/$C$4 -> 0.00098522167 | J7: =D7/$D$4 -> 0
A8: 104 CIERTAS ENF. PREVENIBLES POR VACUNA | B8: 1 | C8: 1 | G8: 104 CIERTAS ENF. PREVENIBLES POR VACUNA | H8: =B8/$B$4 -> 0.00059101655 | I8: =C8/$C$4 -> 0.00098522167 | J8: =D8/$D$4 -> 0
A9: 105 MENINGITIS | B9: 8 | C9: 3 | D9: 5 | G9: 105 MENINGITIS | H9: =B9/$B$4 -> 0.0047281324 | I9: =C9/$C$4 -> 0.002955665 | J9: =D9/$D$4 -> 0.0073855244
A10: 106 SEPTICEMIA | B10: 29 | C10: 16 | D10: 13 | G10: 106 SEPTICEMIA | H10: =B10/$B$4 -> 0.01713948 | I10: =C10/$C$4 -> 0.015763547 | J10: =D10/$D$4 -> 0.019202363
A11: 107 INFECC. CON MODO DE TRANSM. PREDOM./. SEXUAL | B11: 1 | D11: 1 | G11: 107 INFECC. CON MODO DE TRANSM. PREDOM./. SEXUAL | H11: =B11/$B$4 -> 0.00059101655 | I11: =C11/$C$4 -> 0 | J11: =D11/$D$4 -> 0.0014771049
A12: 108 ENFERMEDAD POR EL VIH/SIDA | B12: 20 | C12: 15 | D12: 5 | G12: 108 ENFERMEDAD POR EL VIH/SIDA | H12: =B12/$B$4 -> 0.011820331 | I12: =C12/$C$4 -> 0.014778325 | J12: =D12/$D$4 -> 0.0073855244
A13: 109 INFECCIONES RESPIRATORIAS AGUDAS | B13: 65 | C13: 32 | D13: 33 | G13: 109 INFECCIONES RESPIRATORIAS AGUDAS | H13: =B13/$B$4 -> 0.038416076 | I13: =C13/$C$4 -> 0.031527094 | J13: =D13/$D$4 -> 0.048744461
A14: 110 OTRASENF. INFECCIOSAS Y PARASITARIAS | B14: 3 | C14: 2 | D14: 1 | G14: 110 OTRASENF. INFECCIOSAS Y PARASITARIAS | H14: =B14/$B$4 -> 0.0017730496 | I14: =C14/$C$4 -> 0.0019704433 | J14: =D14/$D$4 -> 0.0014771049
A15: 201 TUMOR MALIGNO DEL ESTOMAGO | B15: 10 | C15: 6 | D15: 4 | G15: 201 TUMOR MALIGNO DEL ESTOMAGO | H15: =B15/$B$4 -> 0.0059101655 | I15: =C15/$C$4 -> 0.00591133 | J15: =D15/$D$4 -> 0.0059084195
A16: 202 TUMOR MALIGNO DEL COLON | B16: 7 | D16: 7 | G16: 202 TUMOR MALIGNO DEL COLON | H16: =B16/$B$4 -> 0.0041371158 | I16: =C16/$C$4 -> 0 | J16: =D16/$D$4 -> 0.010339734
A17: 203 TUMOR M. ORG.DIGESTIVOS Y PERITONEO, EXCL.ESTOM.Y COLON | B17: 8 | C17: 4 | D17: 4 | G17: 203 TUMOR M. ORG.DIGESTIVOS Y PERITONEO, EXCL.ESTOM.Y COLON | H17: =B17/$B$4 -> 0.0047281324 | I17: =C17/$C$4 -> 0.0039408867 | J17: =D17/$D$4 -> 0.0059084195
A18: 204 TUMOR MALIGNO HIGADO Y VIAS BILIARES | B18: 6 | C18: 5 | D18: 1 | G18: 204 TUMOR MALIGNO HIGADO Y VIAS BILIARES | H18: =B18/$B$4 -> 0.0035460993 | I18: =C18/$C$4 -> 0.0049261084 | J18: =D18/$D$4 -> 0.0014771049
A19: 205 TUMOR MALIGNO DEL PANCREAS | B19: 9 | C19: 5 | D19: 4 | G19: 205 TUMOR MALIGNO DEL PANCREAS | H19: =B19/$B$4 -> 0.0053191489 | I19: =C19/$C$4 -> 0.0049261084 | J19: =D19/$D$4 -> 0.0059084195
A20: 206 T. M. DE TRAQUEA, BRONQUIOS Y PULMON | B20: 40 | C20: 21 | D20: 19 | G20: 206 T. M. DE TRAQUEA, BRONQUIOS Y PULMON | H20: =B20/$B$4 -> 0.023640662 | I20: =C20/$C$4 -> 0.020689655 | J20: =D20/$D$4 -> 0.028064993
A21: 207 TUMOR M.ORG. RESPIRAT. E INTRAT., EXCL.TRAQUEA, BRONQUIOS Y PULMON | B21: 6 | C21: 3 | D21: 3 | G21: 207 TUMOR M.ORG. RESPIRAT. E INTRAT., EXCL.TRAQUEA, BRONQUIOS Y PULMON | H21: =B21/$B$4 -> 0.0035460993 | I21: =C21/$C$4 -> 0.002955665 | J21: =D21/$D$4 -> 0.0044313146
A22: 208 TUMOR MALIGNO DE LA MAMA | B22: 10 | D22: 10 | G22: 208 TUMOR MALIGNO DE LA MAMA | H22: =B22/$B$4 -> 0.0059101655 | I22: =C22/$C$4 -> 0 | J22: =D22/$D$4 -> 0.014771049
A23: 209 T. MALIGNO DEL UTERO | B23: 21 | D23: 21 | G23: 209 T. MALIGNO DEL UTERO | H23: =B23/$B$4 -> 0.012411348 | I23: =C23/$C$4 -> 0 | J23: =D23/$D$4 -> 0.031019202
A24: 210 T. MALIGNO DE LA PROSTATA | B24: 22 | C24: 22 | G24: 210 T. MALIGNO DE LA PROSTATA | H24: =B24/$B$4 -> 0.013002364 | I24: =C24/$C$4 -> 0.021674877 | J24: =D24/$D$4 -> 0
A25: 211 T. MALIGNO OTROS ORGANOS GENITOURINARIOS | B25: 7 | C25: 4 | D25: 3 | G25: 211 T. MALIGNO OTROS ORGANOS GENITOURINARIOS | H25: =B25/$B$4 -> 0.0041371158 | I25: =C25/$C$4 -> 0.0039408867 | J25: =D25/$D$4 -> 0.0044313146
A26: 212 T. MALIGNO TEJIDO LINFATICO, ORG. HEMATOPOY. Y TEJIDOS AFINES | B26: 22 | C26: 9 | D26: 13 | G26: 212 T. MALIGNO TEJIDO LINFATICO, ORG. HEMATOPOY. Y TEJIDOS AFINES | H26: =B26/$B$4 -> 0.013002364 | I26: =C26/$C$4 -> 0.0088669951 | J26: =D26/$D$4 -> 0.019202363
A27: 213 RESIDUO DE TUMORES MALIGNOS | B27: 32 | C27: 13 | D27: 19 | G27: 213 RESIDUO DE TUMORES MALIGNOS | H27: =B27/$B$4 -> 0.01891253 | I27: =C27/$C$4 -> 0.012807882 | J27: =D27/$D$4 -> 0.028064993
A28: 214 CARCINOMA IN-SITU, T. BENIGNOS Y DE COMPORTAM.INCIERTO O DESCON. | B28: 3 | C28: 2 | D28: 1 | G28: 214 CARCINOMA IN-SITU, T. BENIGNOS Y DE COMPORTAM.INCIERTO O DESCON. | H28: =B28/$B$4 -> 0.0017730496 | I28: =C28/$C$4 -> 0.0019704433 | J28: =D28/$D$4 -> 0.0014771049
A29: 301 FIEBRE REUMATICA AGUDA Y ENF. CARDIACAS REUM. CRONICAS | B29: 3 | D29: 3 | G29: 301 FIEBRE REUMATICA AGUDA Y ENF. CARDIACAS REUM. CRONICAS | H29: =B29/$B$4 -> 0.0017730496 | I29: =C29/$C$4 -> 0 | J29: =D29/$D$4 -> 0.0044313146
A30: 302 ENFERMEDADES HIPERTENSIVAS | B30: 17 | C30: 6 | D30: 11 | G30: 302 ENFERMEDADES HIPERTENSIVAS | H30: =B30/$B$4 -> 0.010047281 | I30: =C30/$C$4 -> 0.00591133 | J30: =D30/$D$4 -> 0.016248154
A31: 303 ENFERMEDADES ISQUEMICAS DEL CORAZON | B31: 182 | C31: 100 | D31: 82 | G31: 303 ENFERMEDADES ISQUEMICAS DEL CORAZON | H31: =B31/$B$4 -> 0.10756501 | I31: =C31/$C$4 -> 0.098522167 | J31: =D31/$D$4 -> 0.1211226
A32: 304 ENF. CARDIOPULMONAR, DE LA CIRC. PULM. Y OTRAS ENF. CORAZON | B32: 25 | C32: 10 | D32: 15 | G32: 304 ENF. CARDIOPULMONAR, DE LA CIRC. PULM. Y OTRAS ENF. CORAZON | H32: =B32/$B$4 -> 0.014775414 | I32: =C32/$C$4 -> 0.0098522167 | J32: =D32/$D$4 -> 0.022156573
A33: 306 INSUFICIENCOA CARDIACA | B33: 18 | C33: 15 | D33: 3 | G33: 306 INSUFICIENCOA CARDIACA | H33: =B33/$B$4 -> 0.010638298 | I33: =C33/$C$4 -> 0.014778325 | J33: =D33/$D$4 -> 0.0044313146
A34: 307 ENFERMEDADES CEREBROVASCULARES | B34: 101 | C34: 48 | D34: 53 | G34: 307 ENFERMEDADES CEREBROVASCULARES | H34: =B34/$B$4 -> 0.059692671 | I34: =C34/$C$4 -> 0.04729064 | J34: =D34/$D$4 -> 0.078286558
A35: 308 ATEROSCLEROSIS | B35: 1 | C35: 1 | G35: 308 ATEROSCLEROSIS | H35: =B35/$B$4 -> 0.00059101655 | I35: =C35/$C$4 -> 0.00098522167 | J35: =D35/$D$4 -> 0
A36: 309 RESTO ENF. DEL SISTEMA CIRCULATORIO | B36: 10 | C36: 4 | D36: 6 | G36: 309 RESTO ENF. DEL SISTEMA CIRCULATORIO | H36: =B36/$B$4 -> 0.0059101655 | I36: =C36/$C$4 -> 0.0039408867 | J36: =D36/$D$4 -> 0.0088626292
A37: 401 FETO Y RECIEN NACIDO AFECTADOS POR CIERTAS AFECC. MATERNAS | B37: 3 | C37: 2 | D37: 1 | G37: 401 FETO Y RECIEN NACIDO AFECTADOS POR CIERTAS AFECC. MATERNAS | H37: =B37/$B$4 -> 0.0017730496 | I37: =C37/$C$4 -> 0.0019704433 | J37: =D37/$D$4 -> 0.0014771049
A38: 402 FETO Y RECIEN N. AFECTADOS POR COMPL. OBST. Y TRAUM. NACIMIENTO | B38: 5 | C38: 1 | D38: 4 | G38: 402 FETO Y RECIEN N. AFECTADOS POR COMPL. OBST. Y TRAUM. NACIMIENTO | H38: =B38/$B$4 -> 0.0029550827 | I38: =C38/$C$4 -> 0.00098522167 | J38: =D38/$D$4 -> 0.0059084195
A39: 403 RETARDO CRECIM.FETAL, DESNUTR. FETAL., BAJO P./ NACER, GEST.CORTA | B39: 2 | C39: 1 | D39: 1 | G39: 403 RETARDO CRECIM.FETAL, DESNUTR. FETAL., BAJO P./ NACER, GEST.CORTA | H39: =B39/$B$4 -> 0.0011820331 | I39: =C39/$C$4 -> 0.00098522167 | J39: =D39/$D$4 -> 0.0014771049
A40: 404 TRAST. RESPIRATORIOS ESPECIFICOS DEL PERIODO PERINATAL | B40: 76 | C40: 39 | D40: 37 | G40: 404 TRAST. RESPIRATORIOS ESPECIFICOS DEL PERIODO PERINATAL | H40: =B40/$B$4 -> 0.044917258 | I40: =C40/$C$4 -> 0.038423645 | J40: =D40/$D$4 -> 0.05465288
A41: 405 SEPSIS BACTERIANA DEL RECIEN NACIDO | B41: 35 | C41: 16 | D41: 19 | G41: 405 SEPSIS BACTERIANA DEL RECIEN NACIDO | H41: =B41/$B$4 -> 0.020685579 | I41: =C41/$C$4 -> 0.015763547 | J41: =D41/$D$4 -> 0.028064993
...

Sheet DF2005
A1: La Guajira - Riohacha | B1: Rangos de edad | C1: Hombre | D1: Mujer | E1: Total | F1: La Guajira Total | G1: Rangos de edad | H1: Hombre | I1: Mujer | J1: Total | L1: Riohacha PT | M1: Edad | N1: Sexo | Q1: La Guajira PT | R1: Edad | S1: Sexo
B2: 0 a 4 años | C2: 33 | D2: 26 | E2: 59 | G2: 0 a 4 años | H2: 107 | I2: 92 | J2: 199 | N2: Hombre | O2: Mujer | P2: Total | S2: Hombre | T2: Mujer | U2: Total | W2: TBM La Guajira | Y2: =AC2*J24/U118 -> 2.3026828 | AB2: n | AC2: 1000
B3: 5 a 9 años | C3: 5 | D3: 3 | E3: 8 | G3: 5 a 9 años | H3: 16 | I3: 13 | J3: 29 | M3: 0 años | N3: 2856 | O3: 2771 | P3: 5627 | R3: 0 años | S3: 12659 | T3: 12260 | U3: 24919
B4: 10 a 14 años | C4: 10 | D4: 2 | E4: 12 | G4: 10 a 14 años | H4: 26 | I4: 9 | J4: 35 | M4: 1 año | N4: 2647 | O4: 2375 | P4: 5022 | R4: 1 año | S4: 12124 | T4: 11564 | U4: 23688 | AC4: GRÁFICOS
B5: 15 a 19 años | C5: 14 | D5: 4 | E5: 18 | G5: 15 a 19 años | H5: 37 | I5: 17 | J5: 54 | M5: 2 años | N5: 2391 | O5: 2425 | P5: 4816 | R5: 2 años | S5: 11271 | T5: 11064 | U5: 22335 | W5: TBM Riohacha | Y5: =AC2*E24/P112 -> 2.5870318
B6: 20 a 24 años | C6: 21 | D6: 4 | E6: 25 | G6: 20 a 24 años | H6: 75 | I6: 11 | J6: 86 | M6: 3 años | N6: 2225 | O6: 2259 | P6: 4484 | R6: 3 años | S6: 9848 | T6: 9795 | U6: 19643
B7: 25 a 29 años | C7: 20 | D7: - | E7: 20 | G7: 25 a 29 años | H7: 76 | I7: 12 | J7: 88 | M7: 4 años | N7: 2516 | O7: 2385 | P7: 4901 | R7: 4 años | S7: 9629 | T7: 9275 | U7: 18904 | W7: TBMH Guajira | Y7: =AC2*H24/S118 -> 2.8469509
B8: 30 a 34 años | C8: 13 | D8: 3 | E8: 16 | G8: 30 a 34 años | H8: 58 | I8: 13 | J8: 71 | M8: 5 años | N8: 2268 | O8: 2256 | P8: 4524 | R8: 5 años | S8: 9749 | T8: 9251 | U8: 19000 | W8: TBMM Guajira | Y8: =AC2*I24/T118 -> 1.7706602
B9: 35 a 39 años | C9: 18 | D9: 7 | E9: 25 | G9: 35 a 39 años | H9: 62 | I9: 26 | J9: 88 | M9: 6 años | N9: 2032 | O9: 2056 | P9: 4088 | R9: 6 años | S9: 8968 | T9: 8472 | U9: 17440
B10: 40 a 44 años | C10: 16 | D10: 4 | E10: 20 | G10: 40 a 44 años | H10: 55 | I10: 15 | J10: 70 | M10: 7 años | N10: 2050 | O10: 2101 | P10: 4151 | R10: 7 años | S10: 8425 | T10: 8059 | U10: 16484 | W10: TBMH Riohacha | Y10: =AC2*C24/N112 -> 3.2305682
B11: 45 a 49 años | C11: 9 | D11: 4 | E11: 13 | G11: 45 a 49 años | H11: 37 | I11: 19 | J11: 56 | M11: 8 años | N11: 1970 | O11: 1842 | P11: 3812 | R11: 8 años | S11: 8527 | T11: 8066 | U11: 16593 | W11: TBMM Riohacha | Y11: =AC2*D24/O112 -> 1.9732743
B12: 50 a 54 años | C12: 15 | D12: 15 | E12: 30 | G12: 50 a 54 años | H12: 46 | I12: 34 | J12: 80 | M12: 9 años | N12: 1922 | O12: 1766 | P12: 3688 | R12: 9 años | S12: 8033 | T12: 7629 | U12: 15662
B13: 55 a 59 años | C13: 15 | D13: 18 | E13: 33 | G13: 55 a 59 años | H13: 40 | I13: 47 | J13: 87 | M13: 10 años | N13: 1935 | O13: 1912 | P13: 3847 | R13: 10 años | S13: 8224 | T13: 7901 | U13: 16125 | W13: Defunciones La Guajira | Y13: =J24 -> 1507
B14: 60 a 64 años | C14: 7 | D14: 13 | E14: 20 | G14: 60 a 64 años | H14: 33 | I14: 35 | J14: 68 | M14: 11 años | N14: 1849 | O14: 1832 | P14: 3681 | R14: 11 años | S14: 7846 | T14: 7471 | U14: 15317 | W14: Defunciones Riohacha | Y14: =E24 -> 438
B15: 65 a 69 años | C15: 15 | D15: 16 | E15: 31 | G15: 65 a 69 años | H15: 36 | I15: 44 | J15: 80 | M15: 12 años | N15: 1631 | O15: 1738 | P15: 3369 | R15: 12 años | S15: 7257 | T15: 7089 | U15: 14346
B16: 70 a 74 años | C16: 11 | D16: 12 | E16: 23 | G16: 70 a 74 años | H16: 50 | I16: 35 | J16: 85 | M16: 13 años | N16: 1832 | O16: 1863 | P16: 3695 | R16: 13 años | S16: 7588 | T16: 7268 | U16: 14856
B17: 75 a 79 años | C17: 13 | D17: 12 | E17: 25 | G17: 75 a 79 años | H17: 46 | I17: 39 | J17: 85 | M17: 14 años | N17: 1938 | O17: 1900 | P17: 3838 | R17: 14 años | S17: 7243 | T17: 7056 | U17: 14299
B18: 80 a 84 años | C18: 13 | D18: 6 | E18: 19 | G18: 80 a 84 años | H18: 46 | I18: 32 | J18: 78 | M18: 15 años | N18: 1819 | O18: 1851 | P18: 3670 | R18: 15 años | S18: 7379 | T18: 7180 | U18: 14559
B19: 85 a 89 años | C19: 8 | D19: 5 | E19: 13 | G19: 85 a 89 años | H19: 38 | I19: 36 | J19: 74 | M19: 16 años | N19: 1744 | O19: 1829 | P19: 3573 | R19: 16 años | S19: 6466 | T19: 6631 | U19: 13097
B20: 90 a 94 años | C20: 6 | D20: 9 | E20: 15 | G20: 90 a 94 años | H20: 22 | I20: 33 | J20: 55 | M20: 17 años | N20: 1682 | O20: 1700 | P20: 3382 | R20: 17 años | S20: 6346 | T20: 6088 | U20: 12434
B21: 95 a 99 años | C21: 2 | D21: 8 | E21: 10 | G21: 95 a 99 años | H21: 11 | I21: 22 | J21: 33 | M21: 18 años | N21: 1638 | O21: 1741 | P21: 3379 | R21: 18 años | S21: 5917 | T21: 6048 | U21: 11965
B22: 100 a 104 años | C22: 2 | D22: - | E22: 2 | G22: 100 a 104 años | H22: 3 | I22: 1 | J22: 4 | M22: 19 años | N22: 1394 | O22: 1656 | P22: 3050 | R22: 19 años | S22: 5230 | T22: 5641 | U22: 10871
B23: 110 a 114 años | C23: 1 | D23: - | E23: 1 | G23: 110 a 114 años | H23: 1 | I23: 1 | J23: 2 | M23: 20 años | N23: 1680 | O23: 1796 | P23: 3476 | R23: 20 años | S23: 5836 | T23: 6192 | U23: 12028
B24: Total | C24: 267 | D24: 171 | E24: 438 | G24: Total | H24: 921 | I24: 586 | J24: 1507 | M24: 21 años | N24: 1448 | O24: 1687 | P24: 3135 | R24: 21 años | S24: 5573 | T24: 6024 | U24: 11597
M25: 22 años | N25: 1593 | O25: 1704 | P25: 3297 | R25: 22 años | S25: 5501 | T25: 5638 | U25: 11139
M26: 23 años | N26: 1506 | O26: 1756 | P26: 3262 | R26: 23 años | S26: 5405 | T26: 5958 | U26: 11363
M27: 24 años | N27: 1481 | O27: 1641 | P27: 3122 | R27: 24 años | S27: 5082 | T27: 5344 | U27: 10426
M28: 25 años | N28: 1508 | O28: 1593 | P28: 3101 | R28: 25 años | S28: 5403 | T28: 5713 | U28: 11116
M29: 26 años | N29: 1364 | O29: 1451 | P29: 2815 | R29: 26 años | S29: 4807 | T29: 5271 | U29: 10078
M30: 27 años | N30: 1339 | O30: 1531 | P30: 2870 | R30: 27 años | S30: 4707 | T30: 5459 | U30: 10166
M31: 28 años | N31: 1324 | O31: 1416 | P31: 2740 | R31: 28 años | S31: 4531 | T31: 4783 | U31: 9314
M32: 29 años | N32: 1120 | O32: 1150 | P32: 2270 | R32: 29 años | S32: 3937 | T32: 4174 | U32: 8111
M33: 30 años | N33: 1153 | O33: 1330 | P33: 2483 | R33: 30 años | S33: 4559 | T33: 4981 | U33: 9540
M34: 31 años | N34: 1112 | O34: 1103 | P34: 2215 | R34: 31 años | S34: 3777 | T34: 4091 | U34: 7868
M35: 32 años | N35: 941 | O35: 1118 | P35: 2059 | R35: 32 años | S35: 3735 | T35: 4258 | U35: 7993
M36: 33 años | N36: 1034 | O36: 1118 | P36: 2152 | R36: 33 años | S36: 3748 | T36: 3895 | U36: 7643
... M104: 101 años | N104: 1 | O104: 3 | P104: 4 | R104: 101 años | S104: 1 | T104: 8 | U104: 9
M105: 102 años | N105: 1 | O105: - | P105: 1 | R105: 102 años | S105: 4 | T105: 15 | U105: 19
M106: 103 años | N106: - | O106: 1 | P106: 1 | R106: 103 años | S106: 3 | T106: 3 | U106: 6
M107: 104 años | N107: 1 | O107: 1 | P107: 2 | R107: 104 años | S107: 3 | T107: 3 | U107: 6
...

Sheet TEM2005
A1: Tasas Específicas de Mortalidad
I2: n | J2: 10000
B4: Rangos de edad | C4: Total Defunciones | D4: TEM | H4: Rangos de edad | I4: Total Defunciones | J4: TEM | N4: GRÁFICOS
A5: La Guajira Riohacha | B5: 0 años | C5: 30 | D5: =C5*J2/'DF2005'!P3 -> 53.314377 | G5: La Guajira Total | H5: 0 años | I5: 91 | J5: =I5*J2/'DF2005'!U3 -> 36.518319
B6: 1 a 4 años | C6: 59 | D6: =$J$2*'DF2005'!E2/SUM('DF2005'!P3:P7) -> 23.742455 | H6: 1 a 4 años | I6: 199 | J6: =I6*J2/SUM('DF2005'!U3:U7) -> 18.175342
B7: 5 a 9 años | C7: 8 | D7: =$J$2*'DF2005'!E3/SUM('DF2005'!P8:P12) -> 3.9480827 | H7: 5 a 9 años | I7: 29 | J7: =I7*J2/SUM('DF2005'!U8:U12) -> 3.404595
B8: 10 a 14 años | C8: 12 | D8: =J2*C8/SUM('DF2005'!P13:P17) -> 6.5111232 | H8: 10 a 14 años | I8: 35 | J8: =I8*J2/SUM('DF2005'!U13:U17) -> 4.670216
B9: 15 a 19 años | C9: 18 | D9: =C9*J2/SUM('DF2005'!P18:P22) -> 10.554709 | H9: 15 a 19 años | I9: 54 | J9: =I9*J2/SUM('DF2005'!U18:U22) -> 8.5815084
B10: 20 a 24 años | C10: 25 | D10: =J2*C10/SUM('DF2005'!P23:P27) -> 15.344955 | H10: 20 a 24 años | I10: 86 | J10: =I10*J2/SUM('DF2005'!U23:U27) -> 15.206974
B11: 25 a 29 años | C11: 20 | D11: =C11*J2/SUM('DF2005'!P28:P32) -> 14.496956 | H11: 25 a 29 años | I11: 88 | J11: =I11*J2/SUM('DF2005'!U28:U32) -> 18.038331
B12: 30 a 34 años | C12: 16 | D12: =C12*J2/SUM('DF2005'!P33:P37) -> 14.40144 | H12: 30 a 34 años | I12: 71 | J12: =I12*J2/SUM('DF2005'!U33:U37) -> 17.654665
B13: 35 a 39 años | C13: 25 | D13: =C13*J2/SUM('DF2005'!P38:P42) -> 24.447487 | H13: 35 a 39 años | I13: 88 | J13: =I13*J2/SUM('DF2005'!U38:U42) -> 23.409859
B14: 40 a 44 años | C14: 20 | D14: =C14*J2/SUM('DF2005'!P43:P47) -> 22.182786 | H14: 40 a 44 años | I14: 70 | J14: =I14*J2/SUM('DF2005'!U43:U47) -> 21.653056
B15: 45 a 49 años | C15: 13 | D15: =C15*J2/SUM('DF2005'!P48:P52) -> 17.307948 | H15: 45 a 49 años | I15: 56 | J15: =J2*I15/SUM('DF2005'!U48:U52) -> 20.451391
B16: 50 a 54 años | C16: 30 | D16: =C16*J2/SUM('DF2005'!P53:P57) -> 51.876189 | H16: 50 a 54 años | I16: 80 | J16: =I16*J2/SUM('DF2005'!U53:U57) -> 40.048058
B17: 55 a 59 años | C17: 33 | D17: =C17*J2/SUM('DF2005'!P58:P62) -> 73.825503 | H17: 55 a 59 años | I17: 87 | J17: =I17*J2/SUM('DF2005'!U58:U62) -> 51.962014
B18: 60 a 64 años | C18: 20 | D18: =C18*J2/SUM('DF2005'!P63:P67) -> 59.52381 | H18: 60 a 64 años | I18: 68 | J18: =I18*J2/SUM('DF2005'!U63:U67) -> 54.776865
B19: 65 a 69 años | C19: 31 | D19: =C19*J2/SUM('DF2005'!P68:P72) -> 110.08523 | H19: 65 a 69 años | I19: 80 | J19: =I19*J2/SUM('DF2005'!U68:U72) -> 72.588694
B20: 70 a 74 años | C20: 23 | D20: =C20*J2/SUM('DF2005'!P73:P77) -> 99.480969 | H20: 70 a 74 años | I20: 85 | J20: =I20*J2/SUM('DF2005'!U73:U77) -> 100.74671
B21: 75 a 79 años | C21: 25 | D21: =C21*J2/SUM('DF2005'!P78:P82) -> 259.6054 | H21: 75 a 79 años | I21: 85 | J21: =I21*J2/SUM('DF2005'!U78:U82) -> 170.99175
B22: 80 a 84 años | C22: 19 | D22: =C22*J2/SUM('DF2005'!P83:P87) -> 361.90476 | H22: 80 a 84 años | I22: 78 | J22: =I22*J2/SUM('DF2005'!U83:U87) -> 279.2696
B23: 85 a 89 años | C23: 13 | D23: =C23*J2/SUM('DF2005'!P88:P92) -> 433.33333 | H23: 85 a 89 años | I23: 74 | J23: =I23*J2/SUM('DF2005'!U88:U92) -> 453.98773
B24: 90 a 94 años | C24: 15 | D24: =C24*J2/SUM('DF2005'!P93:P97) -> 980.39216 | H24: 90 a 94 años | I24: 55 | J24: =I24*J2/SUM('DF2005'!U93:U97) -> 833.33333
B25: 95 a 99 años | C25: 10 | D25: =C25*J2/SUM('DF2005'!P98:P102) -> 2083.3333 | H25: 95 a 99 años | I25: 33 | J25: =I25*J2/SUM('DF2005'!U98:U102) -> 1217.7122
B26: 100 a 104 años | C26: 2 | D26: =C26*J2/SUM('DF2005'!P103:P107) -> 1333.3333 | H26: 100 a 104 años | I26: 4 | J26: =I26*J2/SUM('DF2005'!U103:U107) -> 512.82051
B27: 110 a 114 años | C27: 1 | D27: =C27*J2/SUM('DF2005'!P110:P111) -> 1111.1111 | H27: 110 a 114 años | I27: 2 | J27: =I27*J2/SUM('DF2005'!U113:U117) -> 1250

Sheet Análisis Longitudinal
B2: Departamento | C2: Año | D2: Población Total | E2: Urbano | F2: Rural | G2: Crecimiento PT (%) | H2: Crecimiento Urbano (%) | I2: Crecimiento Rural (%) | K2: GRÁFICO
B3: La Guajira | C3: 1998 | D3: 544002 | E3: 382779 | F3: 161223 | G3: =(D4-D3)/D3 -> 0.025718655 | H3: =(E4-E3)/E3 -> 0.010217384 | I3: =(F4-F3)/F3 -> 0.062522097
C4: 1999 | D4: 557993 | E4: 386690 | F4: 171303 | G4: =(D5-D4)/D4 -> 0.025858747 | H4: =(E5-E4)/E4 -> 0.00077064315 | I4: =(F5-F4)/F4 -> 0.082491258
C5: 2000 | D5: 572422 | E5: 386988 | F5: 185434 | G5: =(D6-D5)/D5 -> 0.025909207 | H5: =(E6-E5)/E5 -> -0.011974532 | I5: =(F6-F5)/F5 -> 0.10496996
C6: 2001 | D6: 587253 | E6: 382354 | F6: 204899 | G6: =(D7-D6)/D6 -> 0.025421752 | H6: =(E7-E6)/E6 -> -0.026054389 | I6: =(F7-F6)/F6 -> 0.12147936
C7: 2002 | D7: 602182 | E7: 372392 | F7: 229790 | G7: =(D8-D7)/D7 -> 0.024623785 | H7: =(E8-E7)/E7 -> -0.036343423 | I7: =(F8-F7)/F7 -> 0.12342574
C8: 2003 | D8: 617010 | E8: 358858 | F8: 258152 | G8: =(D9-D8)/D8 -> 0.023797021 | H8: =(E9-E8)/E8 -> -0.037937011 | I8: =(F9-F8)/F8 -> 0.10961372
C9: 2004 | D9: 631693 | E9: 345244 | F9: 286449 | G9: =(D10-D9)/D9 -> 0.022202241 | H9: =(E10-E9)/E9 -> -0.03099547 | I9: =(F10-F9)/F9 -> 0.086319031
C10: 2005 | D10: 645718 | E10: 334543 | F10: 311175 | G10: =(D11-D10)/D10 -> 0.023000753 | H10: =(E11-E10)/E10 -> -0.016909635 | I10: =(F11-F10)/F10 -> 0.065908251
C11: 2006 | D11: 660570 | E11: 328886 | F11: 331684 | G11: =(D12-D11)/D11 -> 0.022810603 | H11: =(E12-E11)/E11 -> -0.0039892242 | I11: =(F12-F11)/F11 -> 0.049384354
C12: 2007 | D12: 675638 | E12: 327574 | F12: 348064 | G12: =(D13-D12)/D12 -> 0.022874675 | H12: =(E13-E12)/E12 -> 0.0061390709 | I12: =(F13-F12)/F12 -> 0.03862508
C13: 2008 | D13: 691093 | E13: 329585 | F13: 361508 | G13: =(D14-D13)/D13 -> 0.022934685 | H13: =(E14-E13)/E13 -> 0.013055813 | I13: =(F14-F13)/F13 -> 0.031941202
C14: 2009 | D14: 706943 | E14: 333888 | F14: 373055 | G14: =(D15-D14)/D14 -> 0.022590223 | H14: =(E15-E14)/E14 -> 0.016882907 | I14: =(F15-F14)/F14 -> 0.027698329
C15: 2010 | D15: 722913 | E15: 339525 | F15: 383388 | G15: =(D16-D15)/D15 -> 0.021897517 | H15: =(E16-E15)/E15 -> 0.01866431 | I15: =(F16-F15)/F15 -> 0.024760817
... C25: 2020 | D25: 964067 | E25: 481253 | F25: 482814 | G25: =(D26-D25)/D25 -> 0.030095419 | H25: =(E26-E25)/E25 -> 0.039644428 | I25: =(F26-F25)/F25 -> 0.020577282
C26: 2021 | D26: 993081 | E26: 500332 | F26: 492749
B29: Departamento | C29: Año | D29: Nacimientos | E29: Cabecera | F29: Centro poblado y Rural Disperso | G29: Año | H29: Crecimiento Vegetativo | I29: Tasa de Crecimiento Vegetativo (%) | J29: Crecimiento Migración Neta | K29: Tasa de Crecimiento Migración Neta (%) | P29: GRÁFICO
B30: La Guajira | C30: 1998 | D30: 9396 | E30: 8126 | F30: 678 | G30: 1998 | H30: =D30-D56 -> 8228 | I30: =(H31-H30)/H30 -> 0.047642197 | J30: =D3-H30 -> 535774 | K30: =(J31-J30)/J30 -> 0.025381971
